Workbook

Sheet Ngày tháng 08
A1: BÁO CƠM TRƯA - CHIỀU HANSOL THÁNG 08/2026
A2: ăn trưa | B2: DATE | C2: 26 | D2: 27 | E2: 28 | F2: 29 | G2: 30 | H2: 31 | I2: 1 | J2: 2 | K2: 3 | L2: 4 | M2: 5 | N2: 6 | O2: 7 | P2: 8 | Q2: 9 | R2: 10 | S2: 11 | T2: 12 | U2: 13 | V2: 14 | W2: 15 | X2: 16 | Y2: 17 | Z2: 18 | AA2: 19 | AB2: 20 | AC2: 21 | AD2: 22 | AE2: 23 | AF2: 24 | AG2: 25 | AH2: TOTAL | AI2: NOTE
B3: GA | C3: 5 | D3: 17 | E3: 13 | F3: 17 | G3: 17 | H3: 17 | I3: 7 | J3: 7 | K3: 17 | L3: 16 | M3: 16 | N3: 16 | O3: 17 | P3: 8 | Q3: 6 | R3: 17 | S3: 17 | T3: 17 | U3: 17 | V3: 17 | W3: 6 | X3: 4 | Y3: 17 | Z3: 17 | AA3: 17 | AB3: 17 | AC3: 17 | AD3: 17 | AE3: 5 | AF3: 17 | AG3: 17 | AH3: =SUM(C3:AG3)
B4: HR | D4: 5 | F4: 5 | G4: 5 | H4: 5 | K4: 5 | L4: 5 | M4: 5 | N4: 5 | O4: 4 | R4: 5 | S4: 5 | T4: 5 | U4: 5 | V4: 5 | Y4: 5 | Z4: 5 | AA4: 5 | AB4: 5 | AC4: 5 | AD4: 5 | AF4: 5 | AG4: 5 | AH4: =SUM(C4:AG4) | AM4: Giá tiền | AN4: Ca trưa | AO4: Ca chiều | AP4: Ca tối | AQ4: Ca sáng | AR4: Cơm hàn
B5: ACC | D5: 6 | F5: 6 | G5: 6 | H5: 6 | I5: 6 | J5: 6 | K5: 5 | L5: 6 | M5: 6 | N5: 6 | O5: 6 | R5: 5 | S5: 5 | T5: 6 | U5: 6 | V5: 6 | Y5: 5 | Z5: 6 | AA5: 6 | AB5: 6 | AC5: 6 | AD5: 6 | AF5: 6 | AG5: 6 | AH5: =SUM(C5:AG5) | AM5: 24000 | AN5: =(AH22 - (M22 + T22 + Z22)) * AM5 | AO5: =AH41 * AM5 | AP5: =('Đêm tháng 08'!AH19 - ('Đêm tháng 08'!M19 + 'Đêm tháng 08'!T19 + 'Đêm tháng 08'!AA19)) * AM5 | AQ5: ='Đêm tháng 08'!AH37 * AM5 | AR5: =75000 * ('Cơm Hàn'!E34 + 'Cơm Hàn'!F34)
B6: EX | E6: 5 | F6: 5 | G6: 5 | H6: 4 | I6: 2 | K6: 3 | L6: 4 | M6: 4 | N6: 4 | O6: 4 | P6: 1 | R6: 4 | S6: 4 | T6: 4 | U6: 4 | V6: 4 | Y6: 5 | Z6: 5 | AA6: 5 | AB6: 5 | AC6: 5 | AD6: 5 | AF6: 6 | AG6: 6 | AH6: =SUM(C6:AG6) | AM6: 30000 | AN6: =(M22 + T22 + Z22) * 30000 | AO6: 0 | AP6: =('Đêm tháng 08'!M19 + 'Đêm tháng 08'!T19 + 'Đêm tháng 08'!AA19) * 30000 | AQ6: 0 | AR6: =45000 * 'Cơm Hàn'!D34
B7: IT | C7: 2 | D7: 6 | F7: 6 | G7: 6 | H7: 6 | I7: 2 | J7: 2 | K7: 6 | L7: 6 | M7: 6 | N7: 6 | O7: 6 | P7: 2 | Q7: 2 | R7: 6 | S7: 6 | T7: 6 | U7: 6 | V7: 6 | W7: 1 | X7: 1 | Y7: 6 | Z7: 6 | AA7: 6 | AB7: 6 | AC7: 6 | AD7: 6 | AF7: 6 | AG7: 6 | AH7: =SUM(C7:AG7) | AM7: TỔNG | AN7: =SUM(AN5:AQ6) | AR7: =SUM(AR5:AR6)
B8: HSE | C8: 5 | D8: 7 | E8: 5 | F8: 8 | G8: 7 | H8: 7 | I8: 7 | J8: 4 | K8: 8 | L8: 8 | M8: 8 | N8: 8 | O8: 8 | P8: 7 | Q8: 5 | R8: 8 | S8: 7 | T8: 7 | U8: 7 | V8: 7 | W8: 5 | X8: 5 | Y8: 7 | Z8: 8 | AA8: 8 | AB8: 8 | AC8: 8 | AD8: 7 | AE8: 6 | AF8: 6 | AG8: 6 | AH8: =SUM(C8:AG8)
B9: PUR | E9: 13 | F9: 13 | G9: 14 | H9: 14 | I9: 4 | K9: 13 | L9: 13 | M9: 13 | N9: 12 | O9: 12 | P9: 4 | R9: 13 | S9: 12 | T9: 12 | U9: 12 | V9: 12 | W9: 1 | Y9: 12 | Z9: 12 | AA9: 12 | AB9: 12 | AC9: 12 | AD9: 12 | AF9: 12 | AG9: 12 | AH9: =SUM(C9:AG9)
B10: QC | C10: 42 | D10: 49 | E10: 49 | F10: 50 | G10: 52 | H10: 52 | I10: 48 | J10: 41 | K10: 45 | L10: 45 | M10: 47 | N10: 45 | O10: 47 | P10: 48 | Q10: 36 | R10: 47 | S10: 54 | T10: 49 | U10: 50 | V10: 55 | W10: 50 | X10: 35 | Y10: 53 | Z10: 52 | AA10: 54 | AB10: 50 | AC10: 53 | AD10: 40 | AE10: 29 | AF10: 49 | AG10: 50 | AH10: =SUM(C10:AG10)
B11: MA | C11: 33 | D11: 35 | E11: 35 | F11: 35 | G11: 38 | H11: 35 | I11: 37 | J11: 28 | K11: 32 | L11: 32 | M11: 30 | N11: 32 | O11: 32 | P11: 37 | Q11: 30 | R11: 35 | S11: 35 | T11: 35 | U11: 35 | V11: 31 | W11: 35 | X11: 19 | Y11: 35 | Z11: 35 | AA11: 32 | AB11: 30 | AC11: 30 | AD11: 30 | AE11: 23 | AF11: 32 | AG11: 32 | AH11: =SUM(C11:AG11)
B12: WH | C12: 18 | D12: 20 | E12: 20 | F12: 19 | G12: 20 | H12: 20 | I12: 20 | J12: 18 | K12: 20 | L12: 20 | M12: 21 | N12: 19 | O12: 22 | P12: 20 | Q12: 15 | R12: 21 | S12: 16 | T12: 20 | U12: 16 | V12: 18 | W12: 19 | X12: 3 | Y12: 19 | Z12: 19 | AA12: 20 | AB12: 19 | AC12: 18 | AD12: 18 | AF12: 18 | AG12: 17 | AH12: =SUM(C12:AG12)
B13: 3IN1 | C13: 420 | D13: 475 | E13: 492 | F13: 489 | G13: 493 | H13: 520 | I13: 490 | J13: 490 | K13: 522 | L13: 520 | M13: 520 | N13: 540 | O13: 500 | P13: 475 | Q13: 330 | R13: 524 | S13: 503 | T13: 496 | U13: 497 | V13: 490 | W13: 490 | X13: 230 | Y13: 489 | Z13: 482 | AA13: 438 | AB13: 450 | AC13: 477 | AD13: 500 | AE13: 305 | AF13: 507 | AG13: 455 | AH13: =SUM(C13:AG13)
B14: VPSX | C14: 4 | D14: 6 | E14: 7 | F14: 6 | G14: 6 | H14: 6 | I14: 6 | J14: 6 | K14: 5 | L14: 6 | M14: 7 | N14: 6 | O14: 6 | P14: 5 | Q14: 5 | R14: 6 | S14: 7 | T14: 7 | U14: 7 | V14: 7 | W14: 7 | Y14: 7 | Z14: 8 | AA14: 8 | AB14: 7 | AC14: 8 | AD14: 8 | AE14: 6 | AF14: 8 | AG14: 8 | AH14: =SUM(C14:AG14)
B15: VB | C15: 50 | D15: 50 | E15: 50 | F15: 53 | G15: 50 | H15: 50 | I15: 55 | J15: 55 | K15: 55 | L15: 60 | M15: 60 | N15: 55 | O15: 55 | P15: 50 | Q15: 55 | R15: 66 | S15: 60 | T15: 60 | U15: 60 | V15: 55 | W15: 55 | X15: 55 | Y15: 55 | Z15: 60 | AA15: 55 | AB15: 60 | AC15: 55 | AD15: 55 | AF15: 55 | AG15: 55 | AH15: =SUM(C15:AG15)
B16: KTSP | C16: 27 | D16: 28 | E16: 28 | F16: 29 | G16: 30 | H16: 28 | I16: 30 | J16: 23 | K16: 29 | L16: 30 | M16: 25 | N16: 29 | O16: 28 | P16: 28 | Q16: 25 | R16: 28 | S16: 30 | T16: 30 | U16: 30 | V16: 30 | W16: 30 | X16: 23 | Y16: 30 | Z16: 30 | AA16: 30 | AB16: 30 | AC16: 30 | AD16: 28 | AE16: 15 | AF16: 28 | AG16: 29 | AH16: =SUM(C16:AG16)
B17: KTSX | C17: 20 | D17: 21 | E17: 20 | F17: 21 | G17: 21 | H17: 18 | I17: 20 | J17: 20 | K17: 22 | L17: 22 | M17: 21 | N17: 22 | O17: 21 | P17: 22 | Q17: 22 | R17: 18 | S17: 18 | T17: 21 | U17: 19 | V17: 20 | W17: 20 | X17: 19 | Y17: 18 | Z17: 20 | AA17: 19 | AB17: 19 | AC17: 21 | AD17: 29 | AE17: 18 | AF17: 20 | AG17: 20 | AH17: =SUM(C17:AG17)
B18: SALE | E18: 3 | F18: 3 | G18: 3 | H18: 3 | I18: 2 | K18: 3 | L18: 3 | M18: 3 | N18: 3 | O18: 3 | P18: 1 | R18: 3 | S18: 3 | T18: 3 | U18: 3 | V18: 3 | Y18: 3 | Z18: 3 | AA18: 3 | AB18: 3 | AC18: 3 | AD18: 3 | AF18: 3 | AG18: 3 | AH18: =SUM(C18:AG18)
B19: KHSX | E19: 6 | F19: 6 | G19: 6 | H19: 6 | I19: 4 | K19: 6 | L19: 6 | M19: 6 | N19: 6 | O19: 6 | P19: 5 | Q19: 3 | R19: 6 | S19: 6 | T19: 6 | U19: 6 | V19: 6 | Y19: 6 | Z19: 6 | AA19: 6 | AB19: 6 | AC19: 6 | AD19: 5 | AF19: 6 | AG19: 6 | AH19: =SUM(C19:AG19)
B20: DRIVER | D20: 8 | E20: 5 | F20: 8 | G20: 8 | H20: 8 | I20: 6 | K20: 8 | L20: 8 | M20: 8 | N20: 8 | O20: 8 | P20: 7 | Q20: 7 | R20: 8 | S20: 8 | T20: 8 | U20: 8 | V20: 8 | W20: 2 | Y20: 8 | Z20: 8 | AA20: 8 | AB20: 8 | AC20: 8 | AD20: 8 | AF20: 8 | AG20: 8 | AH20: =SUM(C20:AG20)
B21: SECURITY | C21: 10 | D21: 10 | E21: 10 | F21: 10 | G21: 10 | H21: 10 | I21: 10 | J21: 10 | K21: 10 | L21: 10 | M21: 10 | N21: 10 | O21: 10 | P21: 10 | Q21: 10 | R21: 10 | S21: 10 | T21: 10 | U21: 10 | V21: 10 | W21: 10 | X21: 10 | Y21: 10 | Z21: 10 | AA21: 10 | AB21: 10 | AC21: 10 | AD21: 10 | AE21: 10 | AF21: 10 | AG21: 10 | AH21: =SUM(C21:AG21)
B22: TOTAL | C22: =SUM(C3:C21) | D22: =SUM(D3:D21) | E22: =SUM(E3:E21) | F22: =SUM(F3:F21) | G22: =SUM(G3:G21) | H22: =SUM(H3:H21) | I22: =SUM(I3:I21) | J22: =SUM(J3:J21) | ... AH22: =SUM(AH3:AH21)
B23: GA | D23: 1 | E23: 1 | F23: 1 | G23: 1 | H23: 1 | I23: 1 | J23: 1 | K23: 1 | L23: 1 | M23: 1 | N23: 1 | O23: 1 | Q23: 1 | R23: 1 | S23: 1 | T23: 1 | U23: 1 | V23: 2 | W23: 2 | X23: 2 | Y23: 1 | Z23: 1 | AA23: 1 | AB23: 1 | AC23: 1 | AD23: 1 | AE23: 1 | AF23: 1 | AG23: 1 | AH23: =SUM(C23:AG23)
B24: HR | AH24: =SUM(C24:AG24)
A25: CHIỀU | B25: ACC | D25: 5 | F25: 4 | G25: 4 | H25: 5 | I25: 6 | Q25: 4 | AG25: 4 | AH25: =SUM(C25:AG25)
B26: EX | AH26: =SUM(C26:AG26)
B27: IT | R27: 2 | AH27: =SUM(C27:AG27)
B28: HSE | C28: 4 | D28: 4 | E28: 4 | F28: 4 | G28: 4 | H28: 4 | I28: 5 | J28: 3 | K28: 5 | L28: 5 | M28: 5 | N28: 5 | O28: 5 | P28: 5 | Q28: 5 | R28: 5 | S28: 4 | T28: 4 | U28: 4 | V28: 4 | W28: 5 | X28: 5 | Y28: 4 | Z28: 4 | AA28: 4 | AB28: 4 | AC28: 4 | AD28: 4 | AE28: 4 | AF28: 4 | AG28: 4 | AH28: =SUM(C28:AG28)
B29: PUR | E29: 3 | F29: 5 | G29: 3 | M29: 3 | N29: 3 | O29: 3 | S29: 3 | T29: 3 | U29: 5 | V29: 5 | Y29: 5 | Z29: 5 | AA29: 5 | AB29: 5 | AF29: 3 | AG29: 5 | AH29: =SUM(C29:AG29)
B30: QC | C30: 37 | D30: 43 | E30: 43 | F30: 43 | G30: 43 | H30: 43 | I30: 41 | J30: 37 | K30: 37 | L30: 41 | M30: 34 | N30: 34 | O30: 41 | P30: 38 | Q30: 30 | R30: 37 | S30: 37 | T30: 37 | U30: 37 | V30: 37 | W30: 39 | X30: 29 | Y30: 41 | Z30: 40 | AA30: 40 | AB30: 40 | AC30: 40 | AD30: 25 | AE30: 20 | AF30: 39 | AG30: 39 | AH30: =SUM(C30:AG30)
B31: MA | C31: 20 | D31: 26 | E31: 26 | F31: 26 | G31: 26 | H31: 26 | I31: 20 | J31: 20 | K31: 26 | L31: 24 | M31: 26 | N31: 26 | O31: 26 | P31: 20 | Q31: 20 | R31: 25 | S31: 25 | T31: 25 | U31: 25 | V31: 25 | W31: 20 | X31: 10 | Y31: 25 | Z31: 25 | AA31: 25 | AB31: 25 | AC31: 25 | AD31: 25 | AF31: 25 | AG31: 25 | AH31: =SUM(C31:AG31) | AW31: 5
B32: WH | C32: 18 | D32: 17 | E32: 20 | F32: 19 | G32: 20 | H32: 20 | I32: 20 | J32: 18 | K32: 20 | L32: 20 | M32: 21 | N32: 19 | O32: 20 | P32: 20 | Q32: 15 | R32: 19 | S32: 16 | T32: 18 | U32: 16 | V32: 18 | W32: 19 | X32: 3 | Y32: 18 | Z32: 19 | AA32: 20 | AB32: 19 | AC32: 18 | AD32: 18 | AF32: 18 | AG32: 16 | AH32: =SUM(C32:AG32)
B33: 3IN1 | C33: 420 | D33: 440 | E33: 470 | F33: 480 | G33: 480 | H33: 500 | I33: 490 | J33: 490 | K33: 470 | L33: 490 | M33: 510 | N33: 500 | O33: 485 | P33: 475 | Q33: 330 | R33: 450 | S33: 460 | T33: 460 | U33: 470 | V33: 460 | W33: 460 | X33: 230 | Y33: 440 | Z33: 420 | AA33: 430 | AB33: 450 | AC33: 460 | AD33: 440 | AE33: 280 | AF33: 410 | AG33: 450 | AH33: =SUM(C33:AG33)
B34: VPSX | AH34: =SUM(C34:AG34)
B35: VB | C35: 50 | D35: 45 | E35: 50 | F35: 50 | G35: 50 | H35: 55 | I35: 55 | J35: 55 | K35: 55 | L35: 55 | M35: 55 | N35: 55 | O35: 55 | P35: 50 | Q35: 55 | R35: 50 | S35: 50 | T35: 55 | U35: 50 | V35: 55 | W35: 55 | X35: 55 | Y35: 55 | Z35: 55 | AA35: 55 | AB35: 55 | AC35: 55 | AD35: 45 | AF35: 50 | AG35: 50 | AH35: =SUM(C35:AG35)
B36: KTSP | C36: 21 | D36: 11 | E36: 28 | F36: 19 | G36: 25 | H36: 25 | I36: 28 | J36: 10 | K36: 25 | L36: 27 | M36: 20 | N36: 20 | O36: 20 | P36: 28 | Q36: 15 | R36: 20 | S36: 25 | T36: 25 | U36: 25 | V36: 25 | W36: 28 | X36: 10 | Y36: 25 | Z36: 25 | AA36: 25 | AB36: 25 | AC36: 25 | AD36: 25 | AE36: 25 | AF36: 25 | AG36: 25 | AH36: =SUM(C36:AG36)
B37: KTSX | C37: 20 | D37: 20 | E37: 20 | F37: 20 | G37: 20 | H37: 18 | I37: 20 | J37: 20 | K37: 20 | L37: 20 | M37: 20 | N37: 20 | O37: 20 | P37: 22 | Q37: 22 | R37: 18 | S37: 20 | T37: 20 | U37: 18 | V37: 20 | W37: 20 | X37: 19 | Y37: 18 | Z37: 18 | AA37: 18 | AB37: 18 | AC37: 20 | AD37: 18 | AF37: 20 | AG37: 20 | AH37: =SUM(C37:AG37)
B38: SALE | AH38: =SUM(C38:AG38)
B39: KHSX | D39: 6 | E39: 6 | F39: 6 | G39: 6 | H39: 6 | K39: 6 | L39: 6 | M39: 6 | N39: 6 | O39: 6 | P39: 5 | Q39: 2 | R39: 6 | S39: 6 | T39: 6 | U39: 6 | V39: 6 | Y39: 6 | Z39: 6 | AA39: 6 | AB39: 6 | AC39: 6 | AD39: 4 | AF39: 6 | AG39: 6 | AH39: =SUM(C39:AG39)
B40: DRI | D40: 7 | E40: 7 | F40: 7 | G40: 7 | H40: 7 | I40: 6 | K40: 7 | L40: 7 | M40: 7 | N40: 7 | O40: 7 | P40: 6 | Q40: 5 | R40: 7 | S40: 7 | T40: 7 | U40: 7 | V40: 7 | Y40: 7 | Z40: 7 | AA40: 7 | AB40: 7 | AC40: 7 | AD40: 7 | AF40: 7 | AG40: 7 | AH40: =SUM(C40:AG40)
...

Sheet Đêm tháng 08
B1: BÁO CƠM ĐÊM - SÁNG HANSOL THÁNG 08/2026
A2: ĐÊM | B2: DATE | C2: 26 | D2: 27 | E2: 28 | F2: 29 | G2: 30 | H2: 31 | I2: 1 | J2: 2 | K2: 3 | L2: 4 | M2: 5 | N2: 6 | O2: 7 | P2: 8 | Q2: 9 | R2: 10 | S2: 11 | T2: 12 | U2: 13 | V2: 14 | W2: 15 | X2: 16 | Y2: 17 | Z2: 18 | AA2: 19 | AB2: 20 | AC2: 21 | AD2: 22 | AE2: 23 | AF2: 24 | AG2: 25 | AH2: TOTAL | AI2: NOTE
B3: GA | C3: 1 | D3: 1 | E3: 1 | F3: 1 | G3: 1 | H3: 1 | I3: 1 | J3: 1 | K3: 1 | L3: 1 | M3: 1 | N3: 1 | O3: 1 | P3: 1 | Q3: 1 | R3: 1 | S3: 1 | T3: 1 | U3: 1 | V3: 3 | W3: 2 | Y3: 1 | Z3: 1 | AA3: 1 | AB3: 1 | AC3: 1 | AD3: 1 | AF3: 1 | AG3: 1 | AH3: =SUM(C3:AG3)
B4: HR | AH4: =SUM(C4:AG4)
B5: ACC | AH5: =SUM(C5:AG5)
B6: EX | AH6: =SUM(C6:AG6)
B7: IT | C7: 1 | D7: 1 | E7: 1 | F7: 1 | G7: 1 | H7: 1 | I7: 1 | J7: 1 | K7: 1 | L7: 1 | M7: 1 | N7: 1 | O7: 1 | P7: 1 | Q7: 1 | R7: 1 | S7: 1 | T7: 1 | U7: 1 | V7: 1 | W7: 1 | Y7: 1 | Z7: 1 | AA7: 1 | AB7: 1 | AC7: 1 | AD7: 1 | AF7: 1 | AG7: 1 | AH7: =SUM(C7:AG7)
B8: HSE | C8: 3 | D8: 3 | E8: 4 | F8: 4 | G8: 4 | H8: 4 | I8: 4 | J8: 3 | K8: 4 | L8: 4 | M8: 4 | N8: 4 | O8: 4 | P8: 4 | Q8: 4 | R8: 4 | S8: 4 | T8: 4 | U8: 4 | V8: 4 | W8: 4 | Y8: 4 | Z8: 4 | AA8: 4 | AB8: 4 | AC8: 4 | AD8: 3 | AF8: 4 | AG8: 4 | AH8: =SUM(C8:AG8)
B9: QC | C9: 5 | D9: 33 | E9: 33 | F9: 32 | G9: 33 | H9: 33 | I9: 34 | K9: 34 | L9: 34 | M9: 34 | N9: 34 | O9: 34 | P9: 34 | Q9: 7 | R9: 32 | S9: 31 | T9: 32 | U9: 31 | V9: 31 | W9: 31 | Y9: 33 | Z9: 33 | AA9: 33 | AB9: 33 | AC9: 33 | AD9: 25 | AF9: 33 | AG9: 33 | AH9: =SUM(C9:AG9)
B10: MA | C10: 18 | D10: 24 | E10: 24 | F10: 24 | G10: 24 | H10: 24 | I10: 25 | J10: 5 | K10: 27 | L10: 27 | M10: 27 | N10: 27 | O10: 27 | P10: 28 | Q10: 10 | R10: 27 | S10: 27 | T10: 28 | U10: 28 | V10: 30 | W10: 30 | Y10: 30 | Z10: 31 | AA10: 30 | AB10: 30 | AC10: 30 | AD10: 28 | AF10: 30 | AG10: 30 | AH10: =SUM(C10:AG10)
B11: WH | D11: 11 | E11: 11 | F11: 11 | G11: 11 | H11: 11 | I11: 11 | K11: 11 | L11: 11 | M11: 11 | N11: 11 | O11: 11 | P11: 11 | Q11: 2 | R11: 11 | S11: 12 | T11: 12 | U11: 12 | V11: 12 | W11: 12 | Y11: 12 | Z11: 12 | AA11: 12 | AB11: 12 | AC11: 12 | AD11: 12 | AF11: 12 | AG11: 12 | AH11: =SUM(C11:AG11)
B12: 3IN1 | C12: 20 | D12: 420 | E12: 410 | F12: 410 | G12: 410 | H12: 405 | I12: 390 | J12: 130 | K12: 430 | L12: 420 | M12: 420 | N12: 420 | O12: 405 | P12: 405 | Q12: 120 | R12: 460 | S12: 430 | T12: 430 | U12: 420 | V12: 420 | W12: 420 | Y12: 390 | Z12: 410 | AA12: 400 | AB12: 400 | AC12: 415 | AD12: 400 | AF12: 460 | AG12: 460 | AH12: =SUM(C12:AG12)
B13: VPSX | AH13: =SUM(C13:AG13)
B14: VB | C14: 65 | D14: 60 | E14: 60 | F14: 60 | G14: 55 | H14: 55 | I14: 55 | K14: 55 | L14: 55 | M14: 55 | N14: 55 | O14: 55 | P14: 55 | Q14: 55 | R14: 55 | S14: 50 | T14: 50 | U14: 55 | V14: 55 | W14: 55 | Y14: 50 | Z14: 55 | AA14: 55 | AB14: 55 | AC14: 55 | AD14: 55 | AF14: 55 | AG14: 55 | AH14: =SUM(C14:AG14)
B15: KTSP | C15: 7 | D15: 11 | E15: 11 | F15: 11 | G15: 11 | H15: 11 | I15: 11 | J15: 5 | K15: 11 | L15: 11 | M15: 11 | N15: 11 | O15: 11 | P15: 11 | Q15: 8 | R15: 11 | S15: 11 | T15: 11 | U15: 11 | V15: 11 | W15: 11 | Y15: 11 | Z15: 11 | AA15: 11 | AB15: 11 | AC15: 11 | AD15: 11 | AF15: 11 | AG15: 11 | AH15: =SUM(C15:AG15)
B16: KTSX | D16: 11 | E16: 11 | F16: 11 | G16: 11 | H16: 11 | I16: 11 | J16: 11 | K16: 11 | L16: 11 | M16: 11 | N16: 11 | O16: 11 | P16: 11 | Q16: 8 | R16: 11 | S16: 11 | T16: 11 | U16: 11 | V16: 11 | W16: 13 | Y16: 11 | Z16: 11 | AA16: 11 | AB16: 11 | AC16: 11 | AD16: 11 | AF16: 11 | AG16: 11 | AH16: =SUM(C16:AG16)
B17: DRI | AH17: =SUM(C17:AG17)
B18: SEC | C18: 8 | D18: 8 | E18: 8 | F18: 8 | G18: 8 | H18: 8 | I18: 8 | J18: 8 | K18: 8 | L18: 8 | M18: 8 | N18: 8 | O18: 8 | P18: 8 | Q18: 8 | R18: 8 | S18: 8 | T18: 8 | U18: 8 | V18: 8 | W18: 8 | Y18: 8 | Z18: 8 | AA18: 8 | AB18: 8 | AC18: 8 | AD18: 8 | AF18: 8 | AG18: 8 | AH18: =SUM(C18:AG18)
B19: TOTAL | C19: =SUM(C3:C18) | D19: =SUM(D3:D18) | E19: =SUM(E3:E18) | F19: =SUM(F3:F18) | G19: =SUM(G3:G18) | H19: =SUM(H3:H18) | I19: =SUM(I3:I18) | J19: =SUM(J3:J18) | ... AH19: =SUM(AH3:AH18)
C20: 25 | D20: 26 | E20: 27 | F20: 28 | G20: 29 | H20: 30 | I20: 31 | J20: 1 | K20: 2 | L20: 3 | M20: 4 | N20: 5 | O20: 6 | P20: 7 | Q20: 8 | R20: 9 | S20: 10 | T20: 11 | U20: 12 | V20: 13 | W20: 14 | X20: 15 | Y20: 16 | Z20: 17 | AA20: 18 | AB20: 19 | AC20: 20 | AD20: 21 | AE20: 22 | AF20: 23 | AG20: 24
B21: GA | D21: 1 | E21: 1 | F21: 1 | G21: 1 | H21: 1 | I21: 1 | J21: 1 | K21: 1 | L21: 1 | M21: 1 | N21: 1 | O21: 1 | P21: 1 | Q21: 1 | R21: 1 | S21: 1 | T21: 1 | U21: 1 | V21: 1 | W21: 1 | X21: 2 | Y21: 1 | AA21: 1 | AB21: 1 | AC21: 1 | AD21: 1 | AE21: 1 | AF21: 1 | AH21: =SUM(C21:AG21)
A22: SÁNG | B22: HR | AH22: =SUM(C22:AG22)
B23: ACC | AH23: =SUM(C23:AG23)
B24: EX | AH24: =SUM(C24:AG24)
B25: IT | D25: 1 | E25: 1 | F25: 1 | G25: 1 | H25: 1 | I25: 1 | J25: 1 | K25: 1 | L25: 1 | M25: 1 | N25: 1 | O25: 1 | P25: 1 | Q25: 1 | R25: 1 | S25: 1 | T25: 1 | U25: 1 | V25: 1 | W25: 1 | Y25: 1 | AA25: 1 | AB25: 1 | AC25: 1 | AD25: 1 | AE25: 1 | AF25: 1 | AH25: =SUM(C25:AG25)
B26: HSE | D26: 4 | E26: 3 | F26: 3 | G26: 4 | H26: 4 | I26: 4 | J26: 4 | K26: 4 | L26: 3 | M26: 4 | N26: 4 | O26: 4 | P26: 4 | Q26: 4 | R26: 4 | S26: 4 | T26: 4 | U26: 4 | V26: 4 | W26: 4 | X26: 4 | Y26: 4 | AA26: 4 | AB26: 4 | AC26: 4 | AD26: 4 | AE26: 4 | AF26: 3 | AH26: =SUM(C26:AG26)
B27: QC | D27: 29 | E27: 5 | F27: 32 | G27: 32 | H27: 31 | I27: 30 | J27: 30 | K27: 34 | M27: 32 | N27: 32 | O27: 32 | P27: 32 | Q27: 32 | R27: 34 | S27: 7 | T27: 30 | U27: 31 | V27: 31 | W27: 31 | X27: 31 | Y27: 31 | AA27: 31 | AB27: 30 | AC27: 30 | AD27: 30 | AE27: 30 | AF27: 24 | AH27: =SUM(C27:AG27)
B28: MA | D28: 10 | E28: 10 | F28: 10 | G28: 10 | H28: 10 | I28: 10 | J28: 10 | K28: 10 | L28: 5 | M28: 10 | N28: 10 | O28: 10 | P28: 10 | Q28: 10 | R28: 10 | S28: 5 | T28: 10 | U28: 10 | V28: 10 | W28: 10 | X28: 10 | Y28: 10 | AA28: 10 | AB28: 10 | AC28: 10 | AD28: 10 | AE28: 10 | AF28: 10 | AH28: =SUM(C28:AG28)
B29: WH | D29: 12 | F29: 11 | G29: 11 | H29: 11 | I29: 11 | J29: 11 | K29: 11 | M29: 11 | N29: 11 | O29: 11 | P29: 11 | Q29: 11 | R29: 11 | S29: 2 | T29: 11 | U29: 12 | V29: 12 | W29: 12 | X29: 12 | Y29: 12 | AA29: 12 | AB29: 12 | AC29: 12 | AD29: 12 | AE29: 12 | AF29: 12 | AH29: =SUM(C29:AG29)
B30: 3IN1 | D30: 420 | E30: 20 | F30: 420 | G30: 410 | H30: 410 | I30: 410 | J30: 405 | K30: 390 | L30: 130 | M30: 430 | N30: 420 | O30: 420 | P30: 420 | Q30: 405 | R30: 405 | S30: 120 | T30: 460 | U30: 430 | V30: 430 | W30: 420 | X30: 420 | Y30: 420 | AA30: 390 | AB30: 410 | AC30: 400 | AD30: 400 | AE30: 415 | AF30: 400 | AH30: =SUM(C30:AG30)
B31: VPSX | AH31: =SUM(C31:AG31)
B32: VB | D32: 60 | E32: 65 | F32: 60 | G32: 60 | H32: 60 | I32: 55 | J32: 55 | K32: 55 | M32: 55 | N32: 55 | O32: 55 | P32: 55 | Q32: 55 | R32: 55 | S32: 55 | T32: 55 | U32: 50 | V32: 50 | W32: 55 | X32: 55 | Y32: 55 | AA32: 50 | AB32: 55 | AC32: 55 | AD32: 55 | AE32: 55 | AF32: 55 | AH32: =SUM(C32:AG32)
B33: KTSP | D33: 11 | E33: 7 | F33: 11 | G33: 11 | H33: 11 | I33: 11 | J33: 11 | K33: 11 | L33: 5 | M33: 11 | N33: 11 | O33: 11 | P33: 11 | Q33: 11 | R33: 11 | S33: 8 | T33: 11 | U33: 11 | V33: 11 | W33: 11 | X33: 11 | Y33: 11 | AA33: 11 | AB33: 11 | AC33: 11 | AD33: 11 | AE33: 11 | AF33: 11 | AH33: =SUM(C33:AG33)
B34: KTSX | D34: 11 | F34: 11 | G34: 11 | H34: 11 | I34: 11 | J34: 11 | K34: 11 | L34: 11 | M34: 11 | N34: 11 | O34: 11 | P34: 11 | Q34: 11 | R34: 11 | S34: 8 | T34: 11 | U34: 11 | V34: 11 | W34: 11 | X34: 11 | Y34: 11 | AA34: 11 | AB34: 11 | AC34: 11 | AD34: 11 | AE34: 11 | AF34: 11 | AH34: =SUM(C34:AG34)
B35: DRI | AH35: =SUM(C35:AG35)
B36: SEC | AH36: =SUM(C36:AG36)
B37: TOTAL | C37: =SUM(C21:C36) | D37: =SUM(D21:D36) | E37: =SUM(E21:E36) | F37: =SUM(F21:F36) | G37: =SUM(G21:G36) | H37: =SUM(H21:H36) | I37: =SUM(I21:I36) | J37: =SUM(J21:J36) | ... AI37: =SUM(AI21:AI36)

Sheet Cơm Hàn
A1: THÁNG 08/2026
A2: STT | B2: Ngày | C2: Thứ | D2: Sáng | E2: Trưa | F2: Chiều
A3: 1 | B3: 46229 | C3: Chủ Nhật
A4: 2 | B4: 46230 | C4: Thứ Hai | D4: 25 | E4: 40 | F4: 30
A5: 3 | B5: 46231 | C5: Thứ Ba | D5: 25 | E5: 40 | F5: 30
A6: 4 | B6: 46232 | C6: Thứ Tư | D6: 25 | E6: 35 | F6: 25
A7: 5 | B7: 46233 | C7: Thứ Năm | D7: 25 | E7: 35 | F7: 25
A8: 6 | B8: 46234 | C8: Thứ Sáu | D8: 20 | E8: 30 | F8: 20
A9: 7 | B9: 46235 | C9: Thứ Bảy | D9: 20 | E9: 25
A10: 8 | B10: 46236 | C10: Chủ Nhật
A11: 9 | B11: 46237 | C11: Thứ Hai | D11: 20 | E11: 25 | F11: 20
A12: 10 | B12: 46238 | C12: Thứ Ba | D12: 20 | E12: 25 | F12: 20
A13: 11 | B13: 46239 | C13: Thứ Tư | D13: 20 | E13: 20 | F13: 15
A14: 12 | B14: 46240 | C14: Thứ Năm | D14: 20 | E14: 20 | F14: 15
A15: 13 | B15: 46241 | C15: Thứ Sáu | D15: 20 | E15: 20 | F15: 15
A16: 14 | B16: 46242 | C16: Thứ Bảy | D16: 20 | E16: 20
A17: 15 | B17: 46243 | C17: Chủ Nhật
A18: 16 | B18: 46244 | C18: Thứ Hai | D18: 20 | E18: 20 | F18: 15
A19: 17 | B19: 46245 | C19: Thứ Ba | D19: 20 | E19: 20 | F19: 15
A20: 18 | B20: 46246 | C20: Thứ Tư | D20: 20 | E20: 20 | F20: 15
A21: 19 | B21: 46247 | C21: Thứ Năm | D21: 20 | E21: 20 | F21: 15
A22: 20 | B22: 46248 | C22: Thứ Sáu | D22: 20 | E22: 20
A23: 21 | B23: 46249 | C23: Thứ Bảy | D23: 20 | E23: 20
A24: 22 | B24: 46250 | C24: Chủ Nhật
A25: 23 | B25: 46251 | C25: Thứ Hai | D25: 20 | E25: 20 | F25: 15
A26: 24 | B26: 46252 | C26: Thứ Ba | D26: 20 | E26: 20 | F26: 15
A27: 25 | B27: 46253 | C27: Thứ Tư | D27: 20 | E27: 25 | F27: 15
A28: 26 | B28: 46254 | C28: Thứ Năm | D28: 20 | E28: 25 | F28: 15
A29: 27 | B29: 46255 | C29: Thứ Sáu | D29: 20 | E29: 25 | F29: 15
A30: 28 | B30: 46256 | C30: Thứ Bảy | E30: 25
A31: 29 | B31: 46257 | C31: Chủ Nhật
A32: 30 | B32: 46258 | C32: Thứ Hai | D32: 20 | E32: 25 | F32: 15
A33: 31 | B33: 46259 | C33: Thứ Ba | D33: 20 | E33: 25 | F33: 15
A34: Total | D34: =SUBTOTAL(9, D3:D33) | E34: =SUBTOTAL(9, E3:E33) | F34: =SUBTOTAL(9, F3:F33)
